Workbook

Sheet FLUXO
A1: MARCA | B1: CNPJ/CPF | C1: Nome | D1: EMAIL ENV | E1: CONTATO TEL REAL DEV | F1: CONTATO TEL REC DEV | G1: WHATSAPP MENS REC | H1: WHATSAPP MENS ENV | I1: CORRES DEVEDOR | J1: PROPOSTA | K1: CRVA - SOL | L1: RI SOL | M1: CRVA – POS | N1: RI POS | O1: BUSCA PROCESSUAL NEG | P1: BUSCA PROCESSUAL POS | Q1: 851 SCPC INCLUSAO | R1: CARTA ENVIADA | S1: CARTA DEVOLVIDA | T1: LIGAÇÃO ATIVA
A2: PREPARA | B2: 18.288.085/0001-10 | C2: A & D TREINAMENTOS E CURSOS LTDA - ME | D2: =IF((COUNTIFS(#REF!,$C2,#REF!,"*163*"))>=1,"SIM","") -> #REF! | E2: =IF((COUNTIFS(#REF!,$C2,#REF!,E$1))>=1,"SIM","") -> #REF! | F2: =IF((COUNTIFS(#REF!,$C2,#REF!,F$1))>=1,"SIM","") -> #REF! | G2: =IF((COUNTIFS(#REF!,$C2,#REF!,"*606*"))>=1,"SIM","") -> #REF! | H2: =IF((COUNTIFS(#REF!,$C2,#REF!,"*605*"))>=1,"SIM","") -> #REF! | I2: =IF((COUNTIFS(#REF!,$C2,#REF!,I$1))>=1,"SIM","") -> #REF! | J2: =IF((COUNTIFS(#REF!,$C2,#REF!,J$1))>=1,"SIM","") -> #REF! | K2: =IF((COUNTIFS(#REF!,$C2,#REF!,K$1))>=1,"SIM","") -> #REF! | L2: =IF((COUNTIFS(#REF!,$C2,#REF!,L$1))>=1,"SIM","") -> #REF! | M2: =IF((COUNTIFS(#REF!,$C2,#REF!,M$1))>=1,"SIM","") -> #REF! | N2: =IF((COUNTIFS(#REF!,$C2,#REF!,N$1))>=1,"SIM","") -> #REF! | P2: =IF((COUNTIFS(#REF!,$C2,#REF!,P$1))>=1,"SIM","") -> #REF! | Q2: =IF((COUNTIFS(#REF!,$C2,#REF!,Q$1))>=1,"SIM","") -> #REF! | R2: =IF((COUNTIFS(#REF!,$C2,#REF!,"*CARTA*"))>=1,"SIM","") -> #REF! | S2: =IF((COUNTIFS(#REF!,$C2,#REF!,"*CARTA NOTIFICAÇÃO/DEVOL*"))>=1,"SIM","") -> #REF! | T2: =IF((COUNTIFS(#REF!,$C2,#REF!,"*LIGAÇÃO ATIVA DEV PRIN/LOC*"))>=1,"SIM","") -> #REF!
A3: PREPARA | B3: 18.711.086/0001-26 | C3: A E S COMERCIO DE LIVROS LTDA-ME | D3: =IF((COUNTIFS(#REF!,$C3,#REF!,"*163*"))>=1,"SIM","") -> #REF! | E3: =IF((COUNTIFS(#REF!,$C3,#REF!,E$1))>=1,"SIM","") -> #REF! | F3: =IF((COUNTIFS(#REF!,$C3,#REF!,F$1))>=1,"SIM","") -> #REF! | G3: =IF((COUNTIFS(#REF!,$C3,#REF!,"*606*"))>=1,"SIM","") -> #REF! | H3: =IF((COUNTIFS(#REF!,$C3,#REF!,"*605*"))>=1,"SIM","") -> #REF! | I3: =IF((COUNTIFS(#REF!,$C3,#REF!,I$1))>=1,"SIM","") -> #REF! | J3: =IF((COUNTIFS(#REF!,$C3,#REF!,J$1))>=1,"SIM","") -> #REF! | K3: =IF((COUNTIFS(#REF!,$C3,#REF!,K$1))>=1,"SIM","") -> #REF! | L3: =IF((COUNTIFS(#REF!,$C3,#REF!,L$1))>=1,"SIM","") -> #REF! | M3: =IF((COUNTIFS(#REF!,$C3,#REF!,M$1))>=1,"SIM","") -> #REF! | N3: =IF((COUNTIFS(#REF!,$C3,#REF!,N$1))>=1,"SIM","") -> #REF! | P3: =IF((COUNTIFS(#REF!,$C3,#REF!,P$1))>=1,"SIM","") -> #REF! | Q3: =IF((COUNTIFS(#REF!,$C3,#REF!,Q$1))>=1,"SIM","") -> #REF! | R3: =IF((COUNTIFS(#REF!,$C3,#REF!,"*CARTA*"))>=1,"SIM","") -> #REF! | S3: =IF((COUNTIFS(#REF!,$C3,#REF!,"*CARTA NOTIFICAÇÃO/DEVOL*"))>=1,"SIM","") -> #REF! | T3: =IF((COUNTIFS(#REF!,$C3,#REF!,"*LIGAÇÃO ATIVA DEV PRIN/LOC*"))>=1,"SIM","") -> #REF!
A4: PREPARA | B4: 26.132.015/0001-05 | C4: A F D DA SILVA CURSOS ME | D4: =IF((COUNTIFS(#REF!,$C4,#REF!,"*163*"))>=1,"SIM","") -> #REF! | E4: =IF((COUNTIFS(#REF!,$C4,#REF!,E$1))>=1,"SIM","") -> #REF! | F4: =IF((COUNTIFS(#REF!,$C4,#REF!,F$1))>=1,"SIM","") -> #REF! | G4: =IF((COUNTIFS(#REF!,$C4,#REF!,"*606*"))>=1,"SIM","") -> #REF! | H4: =IF((COUNTIFS(#REF!,$C4,#REF!,"*605*"))>=1,"SIM","") -> #REF! | I4: =IF((COUNTIFS(#REF!,$C4,#REF!,I$1))>=1,"SIM","") -> #REF! | J4: =IF((COUNTIFS(#REF!,$C4,#REF!,J$1))>=1,"SIM","") -> #REF! | K4: =IF((COUNTIFS(#REF!,$C4,#REF!,K$1))>=1,"SIM","") -> #REF! | L4: =IF((COUNTIFS(#REF!,$C4,#REF!,L$1))>=1,"SIM","") -> #REF! | M4: =IF((COUNTIFS(#REF!,$C4,#REF!,M$1))>=1,"SIM","") -> #REF! | N4: =IF((COUNTIFS(#REF!,$C4,#REF!,N$1))>=1,"SIM","") -> #REF! | P4: =IF((COUNTIFS(#REF!,$C4,#REF!,P$1))>=1,"SIM","") -> #REF! | Q4: =IF((COUNTIFS(#REF!,$C4,#REF!,Q$1))>=1,"SIM","") -> #REF! | R4: =IF((COUNTIFS(#REF!,$C4,#REF!,"*CARTA*"))>=1,"SIM","") -> #REF! | S4: =IF((COUNTIFS(#REF!,$C4,#REF!,"*CARTA NOTIFICAÇÃO/DEVOL*"))>=1,"SIM","") -> #REF! | T4: =IF((COUNTIFS(#REF!,$C4,#REF!,"*LIGAÇÃO ATIVA DEV PRIN/LOC*"))>=1,"SIM","") -> #REF!
A5: PREPARA | B5: 26.132.015/0002-88 | C5: A F DA SILVA CURSOS ME | D5: =IF((COUNTIFS(#REF!,$C5,#REF!,"*163*"))>=1,"SIM","") -> #REF! | E5: =IF((COUNTIFS(#REF!,$C5,#REF!,E$1))>=1,"SIM","") -> #REF! | F5: =IF((COUNTIFS(#REF!,$C5,#REF!,F$1))>=1,"SIM","") -> #REF! | G5: =IF((COUNTIFS(#REF!,$C5,#REF!,"*606*"))>=1,"SIM","") -> #REF! | H5: =IF((COUNTIFS(#REF!,$C5,#REF!,"*605*"))>=1,"SIM","") -> #REF! | I5: =IF((COUNTIFS(#REF!,$C5,#REF!,I$1))>=1,"SIM","") -> #REF! | J5: =IF((COUNTIFS(#REF!,$C5,#REF!,J$1))>=1,"SIM","") -> #REF! | K5: =IF((COUNTIFS(#REF!,$C5,#REF!,K$1))>=1,"SIM","") -> #REF! | L5: =IF((COUNTIFS(#REF!,$C5,#REF!,L$1))>=1,"SIM","") -> #REF! | M5: =IF((COUNTIFS(#REF!,$C5,#REF!,M$1))>=1,"SIM","") -> #REF! | N5: =IF((COUNTIFS(#REF!,$C5,#REF!,N$1))>=1,"SIM","") -> #REF! | P5: =IF((COUNTIFS(#REF!,$C5,#REF!,P$1))>=1,"SIM","") -> #REF! | Q5: =IF((COUNTIFS(#REF!,$C5,#REF!,Q$1))>=1,"SIM","") -> #REF! | R5: =IF((COUNTIFS(#REF!,$C5,#REF!,"*CARTA*"))>=1,"SIM","") -> #REF! | S5: =IF((COUNTIFS(#REF!,$C5,#REF!,"*CARTA NOTIFICAÇÃO/DEVOL*"))>=1,"SIM","") -> #REF! | T5: =IF((COUNTIFS(#REF!,$C5,#REF!,"*LIGAÇÃO ATIVA DEV PRIN/LOC*"))>=1,"SIM","") -> #REF!
A6: PREPARA | B6: 40.501.902/0001-26 | C6: A LUZ CURSOS E TREINAMENTOS LTDA | D6: =IF((COUNTIFS(#REF!,$C6,#REF!,"*163*"))>=1,"SIM","") -> #REF! | E6: =IF((COUNTIFS(#REF!,$C6,#REF!,E$1))>=1,"SIM","") -> #REF! | F6: =IF((COUNTIFS(#REF!,$C6,#REF!,F$1))>=1,"SIM","") -> #REF! | G6: =IF((COUNTIFS(#REF!,$C6,#REF!,"*606*"))>=1,"SIM","") -> #REF! | H6: =IF((COUNTIFS(#REF!,$C6,#REF!,"*605*"))>=1,"SIM","") -> #REF! | I6: =IF((COUNTIFS(#REF!,$C6,#REF!,I$1))>=1,"SIM","") -> #REF! | J6: =IF((COUNTIFS(#REF!,$C6,#REF!,J$1))>=1,"SIM","") -> #REF! | K6: =IF((COUNTIFS(#REF!,$C6,#REF!,K$1))>=1,"SIM","") -> #REF! | L6: =IF((COUNTIFS(#REF!,$C6,#REF!,L$1))>=1,"SIM","") -> #REF! | M6: =IF((COUNTIFS(#REF!,$C6,#REF!,M$1))>=1,"SIM","") -> #REF! | N6: =IF((COUNTIFS(#REF!,$C6,#REF!,N$1))>=1,"SIM","") -> #REF! | P6: =IF((COUNTIFS(#REF!,$C6,#REF!,P$1))>=1,"SIM","") -> #REF! | Q6: =IF((COUNTIFS(#REF!,$C6,#REF!,Q$1))>=1,"SIM","") -> #REF! | R6: =IF((COUNTIFS(#REF!,$C6,#REF!,"*CARTA*"))>=1,"SIM","") -> #REF! | S6: =IF((COUNTIFS(#REF!,$C6,#REF!,"*CARTA NOTIFICAÇÃO/DEVOL*"))>=1,"SIM","") -> #REF! | T6: =IF((COUNTIFS(#REF!,$C6,#REF!,"*LIGAÇÃO ATIVA DEV PRIN/LOC*"))>=1,"SIM","") -> #REF!
A7: PREPARA | B7: 18.685.720/0003-65 | C7: A P L DOURADO CENTRO DE TREINAMENTOS | D7: =IF((COUNTIFS(#REF!,$C7,#REF!,"*163*"))>=1,"SIM","") -> #REF! | E7: =IF((COUNTIFS(#REF!,$C7,#REF!,E$1))>=1,"SIM","") -> #REF! | F7: =IF((COUNTIFS(#REF!,$C7,#REF!,F$1))>=1,"SIM","") -> #REF! | G7: =IF((COUNTIFS(#REF!,$C7,#REF!,"*606*"))>=1,"SIM","") -> #REF! | H7: =IF((COUNTIFS(#REF!,$C7,#REF!,"*605*"))>=1,"SIM","") -> #REF! | I7: =IF((COUNTIFS(#REF!,$C7,#REF!,I$1))>=1,"SIM","") -> #REF! | J7: =IF((COUNTIFS(#REF!,$C7,#REF!,J$1))>=1,"SIM","") -> #REF! | K7: =IF((COUNTIFS(#REF!,$C7,#REF!,K$1))>=1,"SIM","") -> #REF! | L7: =IF((COUNTIFS(#REF!,$C7,#REF!,L$1))>=1,"SIM","") -> #REF! | M7: =IF((COUNTIFS(#REF!,$C7,#REF!,M$1))>=1,"SIM","") -> #REF! | N7: =IF((COUNTIFS(#REF!,$C7,#REF!,N$1))>=1,"SIM","") -> #REF! | P7: =IF((COUNTIFS(#REF!,$C7,#REF!,P$1))>=1,"SIM","") -> #REF! | Q7: =IF((COUNTIFS(#REF!,$C7,#REF!,Q$1))>=1,"SIM","") -> #REF! | R7: =IF((COUNTIFS(#REF!,$C7,#REF!,"*CARTA*"))>=1,"SIM","") -> #REF! | S7: =IF((COUNTIFS(#REF!,$C7,#REF!,"*CARTA NOTIFICAÇÃO/DEVOL*"))>=1,"SIM","") -> #REF! | T7: =IF((COUNTIFS(#REF!,$C7,#REF!,"*LIGAÇÃO ATIVA DEV PRIN/LOC*"))>=1,"SIM","") -> #REF!
A8: PREPARA | B8: 19.110.795/0001-19 | C8: A&L CURSOS E CONSULTORIA LTDA - ME | D8: =IF((COUNTIFS(#REF!,$C8,#REF!,"*163*"))>=1,"SIM","") -> #REF! | E8: =IF((COUNTIFS(#REF!,$C8,#REF!,E$1))>=1,"SIM","") -> #REF! | F8: =IF((COUNTIFS(#REF!,$C8,#REF!,F$1))>=1,"SIM","") -> #REF! | G8: =IF((COUNTIFS(#REF!,$C8,#REF!,"*606*"))>=1,"SIM","") -> #REF! | H8: =IF((COUNTIFS(#REF!,$C8,#REF!,"*605*"))>=1,"SIM","") -> #REF! | I8: =IF((COUNTIFS(#REF!,$C8,#REF!,I$1))>=1,"SIM","") -> #REF! | J8: =IF((COUNTIFS(#REF!,$C8,#REF!,J$1))>=1,"SIM","") -> #REF! | K8: =IF((COUNTIFS(#REF!,$C8,#REF!,K$1))>=1,"SIM","") -> #REF! | L8: =IF((COUNTIFS(#REF!,$C8,#REF!,L$1))>=1,"SIM","") -> #REF! | M8: =IF((COUNTIFS(#REF!,$C8,#REF!,M$1))>=1,"SIM","") -> #REF! | N8: =IF((COUNTIFS(#REF!,$C8,#REF!,N$1))>=1,"SIM","") -> #REF! | P8: =IF((COUNTIFS(#REF!,$C8,#REF!,P$1))>=1,"SIM","") -> #REF! | Q8: =IF((COUNTIFS(#REF!,$C8,#REF!,Q$1))>=1,"SIM","") -> #REF! | R8: =IF((COUNTIFS(#REF!,$C8,#REF!,"*CARTA*"))>=1,"SIM","") -> #REF! | S8: =IF((COUNTIFS(#REF!,$C8,#REF!,"*CARTA NOTIFICAÇÃO/DEVOL*"))>=1,"SIM","") -> #REF! | T8: =IF((COUNTIFS(#REF!,$C8,#REF!,"*LIGAÇÃO ATIVA DEV PRIN/LOC*"))>=1,"SIM","") -> #REF!
A9: PREPARA | B9: 13.509.635/0001-60 | C9: A. J. CURSOS PROFISSIONALIZANTES LTDA ME | D9: =IF((COUNTIFS(#REF!,$C9,#REF!,"*163*"))>=1,"SIM","") -> #REF! | E9: =IF((COUNTIFS(#REF!,$C9,#REF!,E$1))>=1,"SIM","") -> #REF! | F9: =IF((COUNTIFS(#REF!,$C9,#REF!,F$1))>=1,"SIM","") -> #REF! | G9: =IF((COUNTIFS(#REF!,$C9,#REF!,"*606*"))>=1,"SIM","") -> #REF! | H9: =IF((COUNTIFS(#REF!,$C9,#REF!,"*605*"))>=1,"SIM","") -> #REF! | I9: =IF((COUNTIFS(#REF!,$C9,#REF!,I$1))>=1,"SIM","") -> #REF! | J9: =IF((COUNTIFS(#REF!,$C9,#REF!,J$1))>=1,"SIM","") -> #REF! | K9: =IF((COUNTIFS(#REF!,$C9,#REF!,K$1))>=1,"SIM","") -> #REF! | L9: =IF((COUNTIFS(#REF!,$C9,#REF!,L$1))>=1,"SIM","") -> #REF! | M9: =IF((COUNTIFS(#REF!,$C9,#REF!,M$1))>=1,"SIM","") -> #REF! | N9: =IF((COUNTIFS(#REF!,$C9,#REF!,N$1))>=1,"SIM","") -> #REF! | P9: =IF((COUNTIFS(#REF!,$C9,#REF!,P$1))>=1,"SIM","") -> #REF! | Q9: =IF((COUNTIFS(#REF!,$C9,#REF!,Q$1))>=1,"SIM","") -> #REF! | R9: =IF((COUNTIFS(#REF!,$C9,#REF!,"*CARTA*"))>=1,"SIM","") -> #REF! | S9: =IF((COUNTIFS(#REF!,$C9,#REF!,"*CARTA NOTIFICAÇÃO/DEVOL*"))>=1,"SIM","") -> #REF! | T9: =IF((COUNTIFS(#REF!,$C9,#REF!,"*LIGAÇÃO ATIVA DEV PRIN/LOC*"))>=1,"SIM","") -> #REF!
A10: PREPARA | B10: 14.107.024/0001-59 | C10: A2E EMPRESARIAL LTDA | D10: =IF((COUNTIFS(#REF!,$C10,#REF!,"*163*"))>=1,"SIM","") -> #REF! | E10: =IF((COUNTIFS(#REF!,$C10,#REF!,E$1))>=1,"SIM","") -> #REF! | F10: =IF((COUNTIFS(#REF!,$C10,#REF!,F$1))>=1,"SIM","") -> #REF! | G10: =IF((COUNTIFS(#REF!,$C10,#REF!,"*606*"))>=1,"SIM","") -> #REF! | H10: =IF((COUNTIFS(#REF!,$C10,#REF!,"*605*"))>=1,"SIM","") -> #REF! | I10: =IF((COUNTIFS(#REF!,$C10,#REF!,I$1))>=1,"SIM","") -> #REF! | J10: =IF((COUNTIFS(#REF!,$C10,#REF!,J$1))>=1,"SIM","") -> #REF! | K10: =IF((COUNTIFS(#REF!,$C10,#REF!,K$1))>=1,"SIM","") -> #REF! | L10: =IF((COUNTIFS(#REF!,$C10,#REF!,L$1))>=1,"SIM","") -> #REF! | M10: =IF((COUNTIFS(#REF!,$C10,#REF!,M$1))>=1,"SIM","") -> #REF! | N10: =IF((COUNTIFS(#REF!,$C10,#REF!,N$1))>=1,"SIM","") -> #REF! | P10: =IF((COUNTIFS(#REF!,$C10,#REF!,P$1))>=1,"SIM","") -> #REF! | Q10: =IF((COUNTIFS(#REF!,$C10,#REF!,Q$1))>=1,"SIM","") -> #REF! | R10: =IF((COUNTIFS(#REF!,$C10,#REF!,"*CARTA*"))>=1,"SIM","") -> #REF! | S10: =IF((COUNTIFS(#REF!,$C10,#REF!,"*CARTA NOTIFICAÇÃO/DEVOL*"))>=1,"SIM","") -> #REF! | T10: =IF((COUNTIFS(#REF!,$C10,#REF!,"*LIGAÇÃO ATIVA DEV PRIN/LOC*"))>=1,"SIM","") -> #REF!
A11: MICROLINS | B11: 30.110.532/0001-42 | C11: A4B PARELHEIROS TECNOLOGIA E TREINAMENTOS LTDA | D11: =IF((COUNTIFS(#REF!,$C11,#REF!,"*163*"))>=1,"SIM","") -> #REF! | E11: =IF((COUNTIFS(#REF!,$C11,#REF!,E$1))>=1,"SIM","") -> #REF! | F11: =IF((COUNTIFS(#REF!,$C11,#REF!,F$1))>=1,"SIM","") -> #REF! | G11: =IF((COUNTIFS(#REF!,$C11,#REF!,"*606*"))>=1,"SIM","") -> #REF! | H11: =IF((COUNTIFS(#REF!,$C11,#REF!,"*605*"))>=1,"SIM","") -> #REF! | I11: =IF((COUNTIFS(#REF!,$C11,#REF!,I$1))>=1,"SIM","") -> #REF! | J11: =IF((COUNTIFS(#REF!,$C11,#REF!,J$1))>=1,"SIM","") -> #REF! | K11: =IF((COUNTIFS(#REF!,$C11,#REF!,K$1))>=1,"SIM","") -> #REF! | L11: =IF((COUNTIFS(#REF!,$C11,#REF!,L$1))>=1,"SIM","") -> #REF! | M11: =IF((COUNTIFS(#REF!,$C11,#REF!,M$1))>=1,"SIM","") -> #REF! | N11: =IF((COUNTIFS(#REF!,$C11,#REF!,N$1))>=1,"SIM","") -> #REF! | P11: =IF((COUNTIFS(#REF!,$C11,#REF!,P$1))>=1,"SIM","") -> #REF! | Q11: =IF((COUNTIFS(#REF!,$C11,#REF!,Q$1))>=1,"SIM","") -> #REF! | R11: =IF((COUNTIFS(#REF!,$C11,#REF!,"*CARTA*"))>=1,"SIM","") -> #REF! | S11: =IF((COUNTIFS(#REF!,$C11,#REF!,"*CARTA NOTIFICAÇÃO/DEVOL*"))>=1,"SIM","") -> #REF! | T11: =IF((COUNTIFS(#REF!,$C11,#REF!,"*LIGAÇÃO ATIVA DEV PRIN/LOC*"))>=1,"SIM","") -> #REF!
A12: MICROLINS | B12: 10.746.134/0001-00 | C12: A4B TECNOLOGIA E TREINAMENTO LTDA | D12: =IF((COUNTIFS(#REF!,$C12,#REF!,"*163*"))>=1,"SIM","") -> #REF! | E12: =IF((COUNTIFS(#REF!,$C12,#REF!,E$1))>=1,"SIM","") -> #REF! | F12: =IF((COUNTIFS(#REF!,$C12,#REF!,F$1))>=1,"SIM","") -> #REF! | G12: =IF((COUNTIFS(#REF!,$C12,#REF!,"*606*"))>=1,"SIM","") -> #REF! | H12: =IF((COUNTIFS(#REF!,$C12,#REF!,"*605*"))>=1,"SIM","") -> #REF! | I12: =IF((COUNTIFS(#REF!,$C12,#REF!,I$1))>=1,"SIM","") -> #REF! | J12: =IF((COUNTIFS(#REF!,$C12,#REF!,J$1))>=1,"SIM","") -> #REF! | K12: =IF((COUNTIFS(#REF!,$C12,#REF!,K$1))>=1,"SIM","") -> #REF! | L12: =IF((COUNTIFS(#REF!,$C12,#REF!,L$1))>=1,"SIM","") -> #REF! | M12: =IF((COUNTIFS(#REF!,$C12,#REF!,M$1))>=1,"SIM","") -> #REF! | N12: =IF((COUNTIFS(#REF!,$C12,#REF!,N$1))>=1,"SIM","") -> #REF! | P12: =IF((COUNTIFS(#REF!,$C12,#REF!,P$1))>=1,"SIM","") -> #REF! | Q12: =IF((COUNTIFS(#REF!,$C12,#REF!,Q$1))>=1,"SIM","") -> #REF! | R12: =IF((COUNTIFS(#REF!,$C12,#REF!,"*CARTA*"))>=1,"SIM","") -> #REF! | S12: =IF((COUNTIFS(#REF!,$C12,#REF!,"*CARTA NOTIFICAÇÃO/DEVOL*"))>=1,"SIM","") -> #REF! | T12: =IF((COUNTIFS(#REF!,$C12,#REF!,"*LIGAÇÃO ATIVA DEV PRIN/LOC*"))>=1,"SIM","") -> #REF!
A13: MICROLINS | B13: 26.801.648/0001-50 | C13: ABJ CURSOS PROFISSIONALIZANTES LTDA ME | D13: =IF((COUNTIFS(#REF!,$C13,#REF!,"*163*"))>=1,"SIM","") -> #REF! | E13: =IF((COUNTIFS(#REF!,$C13,#REF!,E$1))>=1,"SIM","") -> #REF! | F13: =IF((COUNTIFS(#REF!,$C13,#REF!,F$1))>=1,"SIM","") -> #REF! | G13: =IF((COUNTIFS(#REF!,$C13,#REF!,"*606*"))>=1,"SIM","") -> #REF! | H13: =IF((COUNTIFS(#REF!,$C13,#REF!,"*605*"))>=1,"SIM","") -> #REF! | I13: =IF((COUNTIFS(#REF!,$C13,#REF!,I$1))>=1,"SIM","") -> #REF! | J13: =IF((COUNTIFS(#REF!,$C13,#REF!,J$1))>=1,"SIM","") -> #REF! | K13: =IF((COUNTIFS(#REF!,$C13,#REF!,K$1))>=1,"SIM","") -> #REF! | L13: =IF((COUNTIFS(#REF!,$C13,#REF!,L$1))>=1,"SIM","") -> #REF! | M13: =IF((COUNTIFS(#REF!,$C13,#REF!,M$1))>=1,"SIM","") -> #REF! | N13: =IF((COUNTIFS(#REF!,$C13,#REF!,N$1))>=1,"SIM","") -> #REF! | P13: =IF((COUNTIFS(#REF!,$C13,#REF!,P$1))>=1,"SIM","") -> #REF! | Q13: =IF((COUNTIFS(#REF!,$C13,#REF!,Q$1))>=1,"SIM","") -> #REF! | R13: =IF((COUNTIFS(#REF!,$C13,#REF!,"*CARTA*"))>=1,"SIM","") -> #REF! | S13: =IF((COUNTIFS(#REF!,$C13,#REF!,"*CARTA NOTIFICAÇÃO/DEVOL*"))>=1,"SIM","") -> #REF! | T13: =IF((COUNTIFS(#REF!,$C13,#REF!,"*LIGAÇÃO ATIVA DEV PRIN/LOC*"))>=1,"SIM","") -> #REF!
... A783: PEOPLE | B783: 16.746.102/0001-90 | C783: ZESC ZL FORMACAO COMPLETA LTDA | D783: =IF((COUNTIFS(#REF!,$C783,#REF!,"*163*"))>=1,"SIM","") -> #REF! | E783: =IF((COUNTIFS(#REF!,$C783,#REF!,E$1))>=1,"SIM","") -> #REF! | F783: =IF((COUNTIFS(#REF!,$C783,#REF!,F$1))>=1,"SIM","") -> #REF! | G783: =IF((COUNTIFS(#REF!,$C783,#REF!,"*606*"))>=1,"SIM","") -> #REF! | H783: =IF((COUNTIFS(#REF!,$C783,#REF!,"*605*"))>=1,"SIM","") -> #REF! | I783: =IF((COUNTIFS(#REF!,$C783,#REF!,I$1))>=1,"SIM","") -> #REF! | J783: =IF((COUNTIFS(#REF!,$C783,#REF!,J$1))>=1,"SIM","") -> #REF! | K783: =IF((COUNTIFS(#REF!,$C783,#REF!,K$1))>=1,"SIM","") -> #REF! | L783: =IF((COUNTIFS(#REF!,$C783,#REF!,L$1))>=1,"SIM","") -> #REF! | M783: =IF((COUNTIFS(#REF!,$C783,#REF!,M$1))>=1,"SIM","") -> #REF! | N783: =IF((COUNTIFS(#REF!,$C783,#REF!,N$1))>=1,"SIM","") -> #REF! | P783: =IF((COUNTIFS(#REF!,$C783,#REF!,P$1))>=1,"SIM","") -> #REF! | Q783: =IF((COUNTIFS(#REF!,$C783,#REF!,Q$1))>=1,"SIM","") -> #REF! | R783: =IF((COUNTIFS(#REF!,$C783,#REF!,"*CARTA*"))>=1,"SIM","") -> #REF! | S783: =IF((COUNTIFS(#REF!,$C783,#REF!,"*CARTA NOTIFICAÇÃO/DEVOL*"))>=1,"SIM","") -> #REF! | T783: =IF((COUNTIFS(#REF!,$C783,#REF!,"*LIGAÇÃO ATIVA DEV PRIN/LOC*"))>=1,"SIM","") -> #REF!

Sheet AJUIZADOS
A1: MARCA | B1: CNPJ/CPF | C1: NOME | D1: VALOR SISTEMA | E1: VALOR DA CAUSA | F1: DATA INICIO DO FLUXO | G1: AGUARDA PARECER MARCA | H1: AGUARDA PARECER JURÍDICO | I1: AGUARDA PARECER FINANCEIRO | J1: PARECER DESFAVORÁVEL | K1: PARECER OK | L1: AGUARDA PROCURAÇÃO | M1: PRODUÇÃO | N1: PROTOCOLADA | O1: DATA DISTRIBUIÇÃO | P1: Nº DO PROC | Q1: OBSERVAÇÕES
A2: =VLOOKUP(C2,'BASE DE DADOS'!A:B,2,FALSE) -> PREPARA INATIVOS | B2: 18.288.085/0001-10 | C2: A & D TREINAMENTOS E CURSOS LTDA - ME | D2: 247592.84 | E2: 98657.32 | N2: SIM | O2: 44607 | P2: Proc: 1007297-93.2022.8.26.0576
A3: =VLOOKUP(C3,'BASE DE DADOS'!A:B,2,FALSE) -> ENSINA MAIS INATIVOS | B3: 28.081.837/0001-21 | C3: ACS CONSULTORIA EM EDUCACAO TREINAMENTO E CAPACITACAO EIRELI | D3: 10764.75 | E3: 23372.31 | N3: SIM | O3: 44818 | P3: Proc: 1051179-08.2022.8.26.0576 | Q3: ENVIADO EM 05/05/2022.
A4: =VLOOKUP(C4,'BASE DE DADOS'!A:B,2,FALSE) -> PREPARA INATIVOS | B4: 07.243.416/0001-80 | C4: AGF SERVICOES POSTAIS LTDA | D4: 88418.25 | E4: 22921.63 | N4: SIM | O4: 44721 | P4: Proc: 1030490-40.2022.8.26.0576
A5: =VLOOKUP(C5,'BASE DE DADOS'!A:B,2,FALSE) -> ENSINA MAIS INATIVOS | B5: 06.555.129/0001-42 | C5: ALEXANDRE MARIA PETRONILHO ME | D5: 96836.46 | E5: 117836.36 | N5: SIM | O5: 44516 | P5: Proc: 1058279-48.2021.8.26.0576
A6: PREPARA | B6: 21.687.002/0001-70 | C6: ANDERSON CAMARGO BITENCOURT - EIRELI | D6: 19916.34 | E6: 34097.47 | N6: SIM | O6: 44645 | P6: Proc: 10146638620228260576 | Q6: ACORDO FORMALIZADO -
A7: =VLOOKUP(C7,'BASE DE DADOS'!A:B,2,FALSE) -> PREPARA INATIVOS | B7: 10.403.462/0001-03 | C7: APRENDE ILHABELA CURSOS PROFISSIONALIZANTES LTDA | D7: 50921 | E7: 14750.62 | N7: SIM | O7: 44853 | P7: Proc:1058293-95.2022.8.26.0576 | Q7: ENVIADO EM 03/08/2022.
A8: =VLOOKUP(C8,'BASE DE DADOS'!A:B,2,FALSE) -> PREPARA INATIVOS | B8: 10.790.733/0001-20 | C8: ARAUJO & PARANHOS CURSOS PROFISSIONALIZANTES LTDA | D8: 26244.5 | E8: 8997.12 | N8: SIM | O8: 45084 | P8: Proc: 1028212-32.2023.8.26.0576 | Q8: ENVIADO EM 01/09/2022.
A9: =VLOOKUP(C9,'BASE DE DADOS'!A:B,2,FALSE) -> PREPARA INATIVOS | B9: 34.878.293/0001-26 | C9: ARDNAEL CURSOS PROFISSIONALIZANTES LTDA | D9: 87519.41 | E9: 79056.87 | N9: SIM | O9: 45682 | P9: Proc: 1000043-36.2025.8.26.0359 | Q9: ENVIADO EM 22/07/2022. Aguarda baixa, 05/09
A10: =VLOOKUP(C10,'BASE DE DADOS'!A:B,2,FALSE) -> MICROLINS INATIVOS | B10: 07.731.343/0001-75 | C10: B & D FORMACAO PROFISSIONAL LTDA ME | D10: 142117.2 | E10: 236518.82 | N10: SIM | O10: 44691 | P10: Proc: 1019556-51.2022.8.26.0114
A11: =VLOOKUP(C11,'BASE DE DADOS'!A:B,2,FALSE) -> PREPARA INATIVOS | B11: 14.353.416/0001-06 | C11: BOURBON CURSOS PROFISSIONALIZANTES LTDA - ME | D11: 100000 | J11: SIM | Q11: ENVIADO EM 23/03/2022. "A cobrança será ajuizada pelo outro escritório conforme diretriz da Dra. Ana em email enviado para colega Paula".
A12: =VLOOKUP(C12,'BASE DE DADOS'!A:B,2,FALSE) -> PREPARA INATIVOS | B12: 24.680.658/0001-50 | C12: C. C. PORFIRIO - ME | D12: 10468.48 | E12: 18217.98 | N12: SIM | O12: 44573 | P12: Proc: 0009737-11.2024.8.26.0576
A13: =VLOOKUP(C13,'BASE DE DADOS'!A:B,2,FALSE) -> PREPARA INATIVOS | B13: 29.182.183/0001-95 | C13: C.M. DE FREITAS MARTINEZ | D13: 166771.65 | J13: SIM | Q13: OK TÍTULOS BAIXADOS.
A14: =VLOOKUP(C14,'BASE DE DADOS'!A:B,2,FALSE) -> PREPARA INATIVOS | B14: 432.353.598-85 | C14: CAIQUE FARIA TRINDADE | D14: 20707.3 | E14: 30901.51 | N14: SIM | O14: 44657 | P14: Proc: 1017048-07.2022.8.26.0576
A15: =VLOOKUP(C15,'BASE DE DADOS'!A:B,2,FALSE) -> ENSINA MAIS INATIVOS | B15: 17.836.947/0001-30 | C15: CAMINHO BELO COMPLEMENTO ESCOLAR LTDA | D15: 14636.12 | E15: 83388.8 | N15: SIM | O15: 44494 | P15: Proc: 1054440-15.2021.8.26.0576 | R15: 83388.8 | S15: 1054440-15.2021.8.26.0576
A16: =VLOOKUP(C16,'BASE DE DADOS'!A:B,2,FALSE) -> MICROLINS INATIVOS | B16: 03.346.371/0001-18 | C16: CASE-CONSULT. ADM. SERVICOS E EVENTOS LTDA - ME | D16: 20254.85 | E16: 23704.98 | N16: SIM | O16: 44704 | P16: Proc: 1021713-94.2022.8.26.0114 | Q16: ENVIADO EM 03/02/2022, TEM TÍTULOS PRESCRITOS.
A17: =VLOOKUP(C17,'BASE DE DADOS'!A:B,2,FALSE) -> PREPARA INATIVOS | B17: 22.067.184/0001-40 | C17: CAVALCANTE & PANIAGO CURSOS PROFISSIONALIZANTES LT | D17: 31662.01 | E17: 81151.5 | N17: SIM | O17: 44573 | P17: Proc: 1000856-96.2022.8.26.0576
A18: =VLOOKUP(C18,'BASE DE DADOS'!A:B,2,FALSE) -> PREPARA INATIVOS | B18: 10.612.027/0001-99 | C18: CENTRO DE FORMACAO PROFISSIONAL DE ANAPOLIS LTDA | D18: 147520.14 | E18: 99892.9 | N18: SIM | O18: 44981 | P18: Proc: 1009273-04.2023.8.26.0576 | Q18: ENVIADO EM 31/08/2022.
A19: =VLOOKUP(C19,'BASE DE DADOS'!A:B,2,FALSE) -> PREPARA INATIVOS | B19: 10.612.027/0001-99 | C19: CENTRO DE FORMACAO PROFISSIONAL DE ANAPOLIS LTDA | D19: 89958.2 | E19: 89958.2 | N19: SIM | O19: 45180 | P19: Proc: 1045435-95.2023.8.26.0576 | Q19: Ação executiva
A20: PREPARA | B20: 317.192.678-47 | C20: CLEITON ANTONIO LANZA | D20: 20973.11 | J20: SIM
A21: =VLOOKUP(C21,'BASE DE DADOS'!A:B,2,FALSE) -> PREPARA INATIVOS | B21: 14.853.374/0001-64 | C21: CONQUISTA CURSOS PROFISSIONALIZANTES LTDA ME | D21: 75618.75 | E21: 42032.01 | N21: SIM | O21: 44649 | P21: Proc: 1015302-07.2022.8.26.0576
A22: =VLOOKUP(C22,'BASE DE DADOS'!A:B,2,FALSE) -> PREPARA INATIVOS | B22: 13.193.705/0001-14 | C22: CTM CURSOS PROFISSIONALIZANTES LTDA | D22: 120625.82 | E22: 37881.1 | N22: SIM | O22: 44721 | P22: Proc: 1030497-32.2022.8.26.0576 | Q22: AGUARDO GISLAINE SOBRE CHEQUES (OUTRA UNIDADE DO RODRIGO É A CTM)
A23: =VLOOKUP(C23,'BASE DE DADOS'!A:B,2,FALSE) -> PREPARA INATIVOS | B23: 13.193.705/0001-14 | C23: CTM CURSOS PROFISSIONALIZANTES LTDA | D23: 56301.6 | E23: 56301.6 | N23: SIM | O23: 45014 | P23: Proc: 1015680-26.2023.8.26.0576 | Q23: Ajuizada monitória em face de THATIANA RODRIGUES DA COSTA
A24: =VLOOKUP(C24,'BASE DE DADOS'!A:B,2,FALSE) -> PREPARA INATIVOS | B24: 13.567.244/0001-00 | C24: CURSOS PREPARA CAMACARI LTDA | D24: 242985.27 | E24: 28938.63 | N24: SIM | O24: 44791 | P24: Proc: 1045335-77.2022.8.26.0576 | Q24: ENVIADO EM 28/04/2022. Execução
A25: =VLOOKUP(C25,'BASE DE DADOS'!A:B,2,FALSE) -> PREPARA INATIVOS | B25: 13.567.244/0001-00 | C25: CURSOS PREPARA CAMACARI LTDA | D25: 347653.83 | E25: 347653.83 | N25: SIM | O25: 45061 | P25: Proc: 1023794-51.2023.8.26.0576 | Q25: Monitória.
A26: =VLOOKUP(C26,'BASE DE DADOS'!A:B,2,FALSE) -> PREPARA INATIVOS | B26: 30.810.174/0001-80 | C26: CURSOS PREPARA SALVADOR RIO VERMELHO LTDA | D26: 105921.83 | E26: 138189.11 | N26: SIM | O26: 45107 | P26: Proc: 1032264-71.2023.8.26.0576
A27: MICROLINS | B27: 19.510.124/0001-45 | C27: D E F CURSOS PROFISSIONALIZANTES LTDA ME | D27: 379.08 | J27: SIM | Q27: BAIXAS REALIZADAS
A28: =VLOOKUP(C28,'BASE DE DADOS'!A:B,2,FALSE) -> PREPARA INATIVOS | B28: 18.540.892/0001-89 | C28: DAMIAO E LOBO SERVICOS EDUCACIONAIS LTDA | D28: 63160.93 | E28: 70951.22 | N28: SIM | O28: 45005 | P28: Proc: 1013857-17.2023.8.26.0576 | Q28: OBS.: TEM MAIS UMA MONETÓRIAS: N° DE PROCESSO: 1069862-93.2022.8.26.0576 - Data de distribuíção: 17/01/2023 - Valor da Ação: R$ 47.997,93
A29: =VLOOKUP(C29,'BASE DE DADOS'!A:B,2,FALSE) -> PREPARA INATIVOS | B29: 110.862.857-51 | C29: DENYSE ROCHA DA SILVA | D29: 30000 | E29: 84342.17 | N29: SIM | O29: 45036 | P29: Proc: 1019746-49.2023.8.26.0576 | Q29: ENVIADO EM 24/03/2022. Aguarda cópa dos cheques (Taxa de Franquia) da Gislaine, 27/01/2023
A30: =VLOOKUP(C30,'BASE DE DADOS'!A:B,2,FALSE) -> ENSINA MAIS INATIVOS | B30: 130.897.221-00 | C30: DIVINA ARMINDA FERREIRA | D30: 67989.67 | J30: SIM
A31: =VLOOKUP(C31,'BASE DE DADOS'!A:B,2,FALSE) -> PREPARA INATIVOS | B31: 089.925.997-90 | C31: DOUGLAS SANGES LAFERE MESQUITA | D31: 11905.33 | E31: 11905.33 | N31: SIM | O31: 44844 | P31: Proc: 1056686-47.2022.8.26.0576 | Q31: ENVIADO EM 17/06/2022.(Execução)
A32: =VLOOKUP(C32,'BASE DE DADOS'!A:B,2,FALSE) -> PREPARA INATIVOS | B32: 089.925.997-90 | C32: DOUGLAS SANGES LAFERE MESQUITA | D32: 77663.75 | E32: 77663.75 | N32: SIM | O32: 44895 | P32: Proc: 1066618-59.2022.8.26.0576 | Q32: Monitória. Aguarda valor da ação.
A33: =VLOOKUP(C33,'BASE DE DADOS'!A:B,2,FALSE) -> PREPARA INATIVOS | B33: 11.592.964/0001-92 | C33: DR SILVA TREINAMENTOS E CURSOS | D33: 104731.37 | E33: 119146.27 | N33: SIM | O33: 44973 | P33: Proc: 1007672-60.2023.8.26.0576
A34: =VLOOKUP(C34,'BASE DE DADOS'!A:B,2,FALSE) -> MICROLINS | B34: 21.434.842/0002-02 | C34: EDMILSON GOMES PEREIRA | D34: 71640.23 | E34: 121945.92 | N34: SIM | O34: 45026 | P34: Proc: 1050398-14.2022.8.26.0114 | Q34: MC0354
A35: =VLOOKUP(C35,'BASE DE DADOS'!A:B,2,FALSE) -> PREPARA INATIVOS | B35: 13.969.911/0001-73 | C35: EDUCACAO PARA A VIDA CURSOS PROFISSIONALIZANTES LT | D35: 91403.57 | E35: 46632.69 | N35: SIM | O35: 44777 | P35: Proc: 0001480-94.2024.8.26.0576
A36: =VLOOKUP(C36,'BASE DE DADOS'!A:B,2,FALSE) -> ENSINA MAIS INATIVOS | B36: 11.060.716/0001-09 | C36: EDUTEC SERVICOS DE ESC. E TREI. EM DES. PROF. LTDA | D36: 35148.15 | E36: 51061.57 | N36: SIM | O36: 44524 | P36: Proc: 0001482-64.2024.8.26.0576 | S36: 1060118-11.2021.8.26.0576
A37: =VLOOKUP(C37,'BASE DE DADOS'!A:B,2,FALSE) -> PREPARA INATIVOS | B37: 10.635.994/0001-76 | C37: F J CURSOS PROFISSIONALIZANTERS LTDA - ME | D37: 20863.7 | J37: SIM | Q37: ENVIADO EM 17/08/2022. Cheque não possui carimbo de devolução. Solicitei autorização ao Marcelo para baixa 23/02/23.
A38: MICROLINS | B38: 09.674.477/0001-27 | C38: F.K.J FORMACAO PROFISSIONAL LTDA ME | D38: 21061.78 | J38: SIM | Q38: Baixa realizada - Vitória, 26/09.
A39: =VLOOKUP(C39,'BASE DE DADOS'!A:B,2,FALSE) -> PREPARA INATIVOS | B39: 15.872.566/0001-80 | C39: F.T.C DE CASTRO - ME | D39: 23436.3 | E39: 4537.88 | N39: SIM | O39: 44848 | P39: Proc: 1057353-33.2022.8.26.0576 | Q39: ENVIADO EM 12/05/2022.
A40: MICROLINS | B40: 115.821.647-54 | C40: FERNANDO JOSE LEANDRO DE SOUZA | D40: 15561.28 | J40: SIM | Q40: ENVIADO EM 18/04/2022.
...

Sheet LEGENDA
A1: DESFAVORÁVEL
A2: AJUÍZADO / ANDAMENTO
A3: OVVA
A4: CONFERIR / EM ANDAMENTO
A5: PRESCRITOS
A6: AJUÍZADO COM TÍTULOS EM ABERTO
A7: VALOR BAIXO
A8: TAXA DE FRANQUIA (ANÁLISE)

Sheet BASE DE DADOS
A1: CLIENTE | B1: FILIAL
A2: 3 D ILHEUS INFORMATICA LTDA - ME | B2: MICROLINS
A3: 3C SISTEMAS LTDA | B3: PREPARA INATIVOS
A4: 3EMI EMPREENDIMENTOS LTDA ME | B4: PREPARA INATIVOS
A5: 5W2H EDUCACAO LTDA | B5: PREPARA
A6: 5W2H EDUCACAO LTDA | B6: PREPARA INATIVOS
A7: 5W2H EDUCACAO LTDA - ME | B7: PREPARA INATIVOS
A8: A & D EDUCACAO PROFISSIONAL E RECURSOS HUMANOS LTDA | B8: MICROLINS INATIVOS
A9: A & D TREINAMENTOS E CURSOS LTDA - ME | B9: PREPARA INATIVOS
A10: A & G CURSOS LTDA | B10: MICROLINS
A11: A & K CENTRO DE FORMACAO PROFISSIONAL LTDA | B11: MICROLINS
A12: A & S SERVICOS EDUCACIONAIS LTDA - ME | B12: PREPARA INATIVOS
... A2739: ZR TREINAMENTOS LTDA | B2739: MICROLINS

Sheet AJUIZADOS - AC CURSOS
A1: MARCA | B1: CNPJ/CPF | C1: NOME | D1: VALOR SISTEMA | E1: VALOR DA CAUSA | F1: AGUARDA PARECER MARCA | G1: AGUARDA PARECER JURÍDICO | H1: AGUARDA PARECER FINANCEIRO | I1: PARECER OK | J1: AGUARDA PROCURAÇÃO | K1: PRODUÇÃO | L1: PROTOCOLADA | M1: DATA DISTRIBUIÇÃO | N1: Nº DO PROCESSO | O1: OBSERVAÇÕES
A2: PEOPLE | B2: 06.693.085/0001-66 | C2: INTERFOCUS FRIBURGO CAP.PROF. E INF. LTDA | D2: 9329.05 | E2: 12527.04 | L2: SIM | M2: 45537 | N2: 1040108-38.2024.8.26.0576 | O2: PP0202 - AC31126. Enviado em 07/06/2024
A3: PEOPLE | B3: 06.671.085/0001-66 | C3: INTERFOCUS FRIBURGO CAP.PROF. E INF. LTDA | D3: 71304.54 | E3: 85692.93 | L3: SIM | M3: 45537 | N3: 1040155-12.2024.8.26.0576 | O3: PP0202 - AC31130. Enviado em 07/06/2024
A4: PEOPLE | B4: 31.206.339/0001-72 | C4: EDUCATION IN CENTER - CONSULTORIA LTDA | D4: 47544.29 | E4: 105084.64 | L4: SIM | M4: 45610 | N4: 1051748-38.2024.8.26.0576 | O4: PP0217 - AC21326. Enviado em 07/06/2024.
A5: SOS | B5: 20.116.895/0001-31 | C5: CRISANE QUALIFICAÇÃO E IDIOMAS EIRELLI | D5: 98423.34 | E5: 129841.68 | L5: SIM | M5: 45518 | N5: 1036892-69.2024.8.26.0576 | O5: SO0089 - REN3862872957 (AC28229). Enviado em 11/06/2024
A6: SOS | B6: 20.116.895/0001-35 | C6: CRISANE QUALIFICAÇÃO E IDIOMAS EIRELLI | D6: 8949.4 | E6: 14962.57 | L6: SIM | M6: 45516 | N6: 1036531-52.2024.8.26.0576 | O6: SO0089 - REN3862872958 (AC28236). Enviado em 11/06/2024. 1036531-52.2024.8.26.0576
A7: SOS | B7: 09.584.729/0001-27 | C7: MASOFT SISTEMAS LTDA - SKL EDUCAÇÃO E INFORMÁTICA LTDA | D7: 11218.4 | E7: 129841.68 | F7: SIM | O7: SO0084 - REN3862873191 (AC29865). Enviado em 21/06/2024. Devor não é a PJ
A8: MICROLINS | B8: 697.775.432-04 | C8: CLAUDIO DAISHONIN SAUNDERS FLORENCIA | D8: 30213.35 | F8: SIM | O8: MC1340. REN3862872951 (AC32089). Enviado em 09/07/2024
A9: MICROLINS | B9: 37.683.797/0001-89 | C9: ESCOLA PROFISSIONALIZANTE E RECURSOS HUMANOS EIRELI | D9: 36607.37 | F9: SIM | O9: MC1335. REN50043. Enviado em 09/07/2024
A10: MICROLINS | B10: 20.140.534/0001-20 | C10: J.C. FORMACAO PROFISSIONAL LTDA | D10: 26399.83 | E10: 35527.57 | L10: SIM | M10: 45567 | N10: 1044905-57.2024.8.26.0576 | O10: MC0365. REN3862873043 (AC24584). Enviado em 09/07/2024
A11: MICROLINS | B11: 20.140.534/0001-20 | C11: J.C. FORMACAO PROFISSIONAL LTDA | D11: 1645.59 | E11: 2210.92 | L11: SIM | M11: 45554 | N11: 1042876-34.2024.8.26.0576 | O11: MC0365. REN3862873045 (AC30947). Enviado em 09/07/2024
A12: MICROLINS | B12: 20.140.534/0001-20 | C12: J.C. FORMACAO PROFISSIONAL LTDA | D12: 1394.07 | E12: 1612.89 | L12: SIM | M12: 45559 | N12: 1043558-86.2024.8.26.0576 | O12: MC0365. REN3862873044 (AC29669). Enviado em 09/07/2024.
A13: MICROLINS | B13: 05.291.973/0001-40 | C13: HMK CURSOS DE INFORMATICA PROFISSIONALIZANTES S/S LTDA | D13: 114412.9 | E13: 140350.64 | L13: SIM | M13: 45537 | N13: 1040055-57.2024.8.26.0576 | O13: MC0198. REN3862873033 (29996). Enviado em 09/07/2024
A14: MICROLINS | B14: 05.291.793/0001-40 | C14: HMK CURSOS DE INFORMATICA PROFISSIONALIZANTES S/S LTDA | D14: 1670.68 | E14: 2026.6 | L14: SIM | M14: 45520 | N14: 1037421-88.2024.8.26.0576 | O14: MC0198.REN3862873034 (AC1003). Enviado em 09/07/2024
A15: MICROLINS | B15: 088.163.614-25 | C15: KASSIA TASSYANA DOS SANTOS VASCONCELOS MAGALHAES | D15: 171813.16 | E15: 126849.22 | L15: SIM | M15: 45567 | N15: 1044939-32.2024.8.26.0576 | O15: MC0198.REN3862873034 (AC1003). Enviado em 09/07/2024
A16: MICROLINS | B16: 11.362.578/0001-04 | C16: PAZ E CHAVES LTDA | D16: 118672.21 | F16: DESFAVORÁVEL | O16: MC0289. REN3862873141 (AC34442). Enviado em 19/07/2024. Nancy mencionou que a unidade está ativa
A17: MICROLINS | B17: 05.229.602/0001-39 | C17: C & C TREINAMENTOS LTDA | D17: 66734.12 | E17: 94018.12 | L17: SIM | M17: 45631 | O17: MC0147. REN3862872916 (AC30974). Enviado em 29/07/2024. Proc. 1054777-96.2024.8.26.0576
A18: MICROLINS | B18: 05.229.602/0001-39 | C18: C & C TREINAMENTOS LTDA | D18: 1457.81 | L18: SIM | M18: 45631 | O18: MC0147. REN3862872917 (AC32951). Enviado em 29/07/2024 Proc. 1054777-96.2024.8.26.0576
A19: MICROLINS | B19: 05.229.602/0001-39 | C19: C & C TREINAMENTOS LTDA | D19: 11282.44 | L19: SIM | M19: 45631 | O19: MC0147. REN3862872918 (AC 32954). Enviado em 29/07/2024 Proc. 1054777-96.2024.8.26.0576
A20: SOS | B20: 21.556.648/0001-19 | C20: TEMPO SOLUCOES EM EDUCACAO LTDA ME | D20: 2106.36 | E20: 3491.16 | L20: SIM | M20: 45576 | N20: 1046418-60.2024.8.26.0576 | O20: SO0094. REN3862873201 (AC 28894). Enviado em 31/07/2024
A21: SOS | B21: 21.556.648/0001-19 | C21: TEMPO SOLUCOES EM EDUCACAO LTDA ME | D21: 58616.52 | E21: 75152.87 | L21: SIM | M21: 45614 | N21: 1052051-52.2024.8.26.0576 | O21: SO0094. REN3862873202 (AC 28927). Enviado em 31/07/2024
A22: SOS | B22: 17.522.270/0001-65 | C22: MILENIO CURSOS E TREINAMENTOS EIRELI | D22: 12985.78 | E22: 16207.47 | L22: SIM | M22: 45573 | N22: 1045855-66.2024.8.26.0576 | O22: SO0271. REN3862873108 (AC 30995). Enviado em 31/07/2024
A23: MICROLINS | B23: 18.226.478/0001-08 | C23: ECGG CURSOS LTDA - ME | D23: 41639.47 | K23: SIM | O23: MC0361. REN3862872986 (AC 30815). Enviado em 12/08/2024. Devedor não é a PJ
A24: MICROLINS | B24: 26.801.548/0001-50 | C24: ABJ CURSOS PROFISSIONALIZANTES LTDA ME | D24: 6364.86 | F24: SIM | O24: MC0530. REN3862872884 (AC24179). Enviado em 27/08/2024.
A25: PEOPLE | B25: 41.512.896/0001-75 | C25: B&J CURSOS TECNICOS EM INFORMATICA LTDA | D25: 1241.11 | F25: SIM | O25: PP0267. REN3862872911 (AC31033). Enviado e-mail em 12/08/2024. Estão verificando distrato/quitação
A26: MICROLINS | B26: 05.380.319/0001-03 | C26: H B CENTRO DE FORMAÇÃO PROFISSIONAL LTDA | D26: 9066.22 | F26: SIM | O26: MC0300. REN3862873029 (AC23142). Enviado em 29/08/2024
A27: MICROLINS | B27: 12.213.218/0001-03 | C27: JF CURSOS E INFORMATICA LTDA ME | D27: 113623.86 | F27: SIM | O27: MC0237. REN3862873059 (AC 27350). Enviado em 17/09/2024
A28: PEOPLE | B28: 08.893.793/0003-99 | C28: JGM CENTRO DE IDIOMAS LTDA-ME | D28: 208100.69 | F28: SIM | O28: PP0060. REN3862873060 (AC30988). Enviado em 18/09/2024
A29: MICROLINS | B29: 08.335.434/0001-54 | C29: TAIS CRISTINA FRANCISCO ME | D29: 80728.02 | F29: SIM | O29: MC0207. REN3862873197 (AC34480). Enviado em 12/12/2024
A30: MICROLINS | B30: 17.027.496/0001-90 | C30: EDUPRO GUADALUPE LTDA | D30: 46336.12 | F30: SIM | O30: MC0315. REN3862872994 (AC 34337). Enviado em 12/12/2024
A31: MICROLINS | B31: 24.604.424/0001-23 | C31: SAMPAIO PROJETOS E CONSULTORIA | D31: 51863.28 | F31: SIM | O31: MC0260. REN3862873180 (AC 24258). Enviado em 13/12/2024
A32: MICROLINS | B32: 36.562.622/0001-50 | C32: ART CRIS TREINAMENTOS E DESENVOLVIMENTO LTDA | D32: 10316.29 | F32: SIM | O32: MC1626. REN50143. Enviado em 18/12/2024

Sheet PAINEL Novo
